Workbook

Sheet מודל_עסקה
A1: מודל חיתום פליפ — אינדיאנפוליס
A2: צהוב = תא קלט. שחור = נוסחה. עדכן רק את התאים הצהובים.
A3: א. נכס ועסקה
A4: ZIP | B4: 46236
A5: שטח בנוי (sqft) | B5: 1400
A6: שנת בנייה | B6: 1993 | C6: <1978 ⇒ חלה חובת EPA RRP
A7: ARV לרגל רבוע ($/sqft) | B7: 215 | C7: קלט. מ-python3 arv.py comps / listings.py: ARV ÷ sqft. המכפיל 1.18 נפסל (decisions.md 6.9.2026)
A8: ARV גולמי | B8: =B5*B7
A9: מחיר רכישה | B9: 180000
A11: ב. שיפוץ
A12: עלות בסיס $/sqft | B12: 32 | C12: אינדי 2026: קל 12-20 · בינוני 25-42 · גוט 45-75
A13: תוספת מלאי טרום-1978 $/sqft | B13: 8 | C13: עופרת, אסבסט, מגולוון, חיווט אלומיניום
A14: $/sqft אפקטיבי | B14: =IF(B6<1978,B12+B13,B12)
A15: עלות שיפוץ בסיס | B15: =B5*B14
A16: רזרבה % | B16: 0.17 | C16: 15%-20% על מלאי טרום-1970. MEP הוא מקור החריגה ב-2026
A17: סה"כ שיפוץ | B17: =B15*(1+B16)
A19: ג. עלויות רכישה
A20: טייטל, סגירה, עו"ד | B20: 2000
A21: בדיקה, שמאות, סקר | B21: 900
A22: אגרות רישום | B22: 65 | C22: אינדיאנה: $35 שטר + $10 מבקר + $20 SDF · מס העברה מדינתי $0
A23: היתרים | B23: 900 | C23: מבני $390 · מטבח/אמבט מלא ~$712 · בדיקה 15-20 ימי עסקים
A24: סה"כ עלויות רכישה | B24: =SUM(B20:B23)
A26: ד. לוח זמנים
A27: חודשי שיפוץ | B27: 5
A28: ימים בשוק (DOM) | B28: 30 | C28: זיפ 46236: 18 · אבל Marion County מדיאן 25 ו-Center Twp 41
A29: ימי סגירה | B29: 35
A30: סה"כ חודשי החזקה | B30: =B27+(B28+B29)/30.4
A31: מחזורים בשנה | B31: =12/(B30+1.5) | C31: +1.5 ח' חיפוש וסגירה של העסקה הבאה (~45 יום). היה 12/B30
A33: ה. עלויות החזקה
A34: שווי שומה (AV) | B34: 150000 | C34: נמוך ממחיר השוק בדרך כלל. לאמת בטופס 11
A35: תקרת מס רכוש אינדיאנה | B35: 0.02 | C35: IC 6-1.1-20.6-4(1): 2% למגורים לא-מאוכלס-בעלים ב-LLC
A36: מס רכוש שנתי | B36: =B34*B35
A37: ביטוח builder's risk שנתי | B37: 2200 | C37: ⚠️ לוודא בכתב אם ההשתתפות לרוח/ברד היא $ קבוע או % מהכיסוי
A38: יוטיליטיס חודשי | B38: 180
A39: אבטחה, גינון, אחר חודשי | B39: 150
A40: סה"כ חודשי | B40: =B36/12+B37/12+B38+B39
A41: סה"כ עלויות החזקה | B41: =B40*B30
A43: ו. מימון — 0% בשתי השורות = מזומן מלא
A44: LTC על הרכישה % | B44: 0 | C44: 0% = מזומן מלא (ברירת המחדל). ממונף: Kiavi עד 95% · Lima One 90-95%
A45: % מימון השיפוץ | B45: 0 | C45: 0% = מזומן מלא
...

Sheet רגישויות
A1: רגישויות — רווח גולמי בדולרים
A2: שורות = סטיית עלות השיפוץ · עמודות = סטיית מחיר המכירה
A4: עלות שיפוץ ↓ / מחיר מכירה ← | B4: -0.15 | C4: -0.1 | D4: -0.05 | E4: 0 | F4: 0.05
A5: -0.1 | B5: =(מודל_עסקה!$B$59*(1+B$4))*(1-SUM(מודל_עסקה!$B$60:$B$63))-(מודל_עסקה!$B$54+מודל_עסקה!$B$17*$A5) | C5: =(מודל_עסקה!$B$59*(1+C$4))*(1-SUM(מודל_עסקה!$B$60:$B$63))-(מודל_עסקה!$B$54+מודל_עסקה!$B$17*$A5) | D5: =(מודל_עסקה!$B$59*(1+D$4))*(1-SUM(מודל_עסקה!$B$60:$B$63))-(מודל_עסקה!$B$54+מודל_עסקה!$B$17*$A5) | E5: =(מודל_עסקה!$B$59*(1+E$4))*(1-SUM(מודל_עסקה!$B$60:$B$63))-(מודל_עסקה!$B$54+מודל_עסקה!$B$17*$A5) | F5: =(מודל_עסקה!$B$59*(1+F$4))*(1-SUM(מודל_עסקה!$B$60:$B$63))-(מודל_עסקה!$B$54+מודל_עסקה!$B$17*$A5)
A6: 0 | B6: =(מודל_עסקה!$B$59*(1+B$4))*(1-SUM(מודל_עסקה!$B$60:$B$63))-(מודל_עסקה!$B$54+מודל_עסקה!$B$17*$A6) | C6: =(מודל_עסקה!$B$59*(1+C$4))*(1-SUM(מודל_עסקה!$B$60:$B$63))-(מודל_עסקה!$B$54+מודל_עסקה!$B$17*$A6) | D6: =(מודל_עסקה!$B$59*(1+D$4))*(1-SUM(מודל_עסקה!$B$60:$B$63))-(מודל_עסקה!$B$54+מודל_עסקה!$B$17*$A6) | E6: =(מודל_עסקה!$B$59*(1+E$4))*(1-SUM(מודל_עסקה!$B$60:$B$63))-(מודל_עסקה!$B$54+מודל_עסקה!$B$17*$A6) | F6: =(מודל_עסקה!$B$59*(1+F$4))*(1-SUM(מודל_עסקה!$B$60:$B$63))-(מודל_עסקה!$B$54+מודל_עסקה!$B$17*$A6)
A7: 0.1 | B7: =(מודל_עסקה!$B$59*(1+B$4))*(1-SUM(מודל_עסקה!$B$60:$B$63))-(מודל_עסקה!$B$54+מודל_עסקה!$B$17*$A7) | C7: =(מודל_עסקה!$B$59*(1+C$4))*(1-SUM(מודל_עסקה!$B$60:$B$63))-(מודל_עסקה!$B$54+מודל_עסקה!$B$17*$A7) | D7: =(מודל_עסקה!$B$59*(1+D$4))*(1-SUM(מודל_עסקה!$B$60:$B$63))-(מודל_עסקה!$B$54+מודל_עסקה!$B$17*$A7) | E7: =(מודל_עסקה!$B$59*(1+E$4))*(1-SUM(מודל_עסקה!$B$60:$B$63))-(מודל_עסקה!$B$54+מודל_עסקה!$B$17*$A7) | F7: =(מודל_עסקה!$B$59*(1+F$4))*(1-SUM(מודל_עסקה!$B$60:$B$63))-(מודל_עסקה!$B$54+מודל_עסקה!$B$17*$A7)
A8: 0.2 | B8: =(מודל_עסקה!$B$59*(1+B$4))*(1-SUM(מודל_עסקה!$B$60:$B$63))-(מודל_עסקה!$B$54+מודל_עסקה!$B$17*$A8) | C8: =(מודל_עסקה!$B$59*(1+C$4))*(1-SUM(מודל_עסקה!$B$60:$B$63))-(מודל_עסקה!$B$54+מודל_עסקה!$B$17*$A8) | D8: =(מודל_עסקה!$B$59*(1+D$4))*(1-SUM(מודל_עסקה!$B$60:$B$63))-(מודל_עסקה!$B$54+מודל_עסקה!$B$17*$A8) | E8: =(מודל_עסקה!$B$59*(1+E$4))*(1-SUM(מודל_עסקה!$B$60:$B$63))-(מודל_עסקה!$B$54+מודל_עסקה!$B$17*$A8) | F8: =(מודל_עסקה!$B$59*(1+F$4))*(1-SUM(מודל_עסקה!$B$60:$B$63))-(מודל_עסקה!$B$54+מודל_עסקה!$B$17*$A8)
A9: 0.3 | B9: =(מודל_עסקה!$B$59*(1+B$4))*(1-SUM(מודל_עסקה!$B$60:$B$63))-(מודל_עסקה!$B$54+מודל_עסקה!$B$17*$A9) | C9: =(מודל_עסקה!$B$59*(1+C$4))*(1-SUM(מודל_עסקה!$B$60:$B$63))-(מודל_עסקה!$B$54+מודל_עסקה!$B$17*$A9) | D9: =(מודל_עסקה!$B$59*(1+D$4))*(1-SUM(מודל_עסקה!$B$60:$B$63))-(מודל_עסקה!$B$54+מודל_עסקה!$B$17*$A9) | E9: =(מודל_עסקה!$B$59*(1+E$4))*(1-SUM(מודל_עסקה!$B$60:$B$63))-(מודל_עסקה!$B$54+מודל_עסקה!$B$17*$A9) | F9: =(מודל_עסקה!$B$59*(1+F$4))*(1-SUM(מודל_עסקה!$B$60:$B$63))-(מודל_עסקה!$B$54+מודל_עסקה!$B$17*$A9)
A10: 0.4 | B10: =(מודל_עסקה!$B$59*(1+B$4))*(1-SUM(מודל_עסקה!$B$60:$B$63))-(מודל_עסקה!$B$54+מודל_עסקה!$B$17*$A10) | C10: =(מודל_עסקה!$B$59*(1+C$4))*(1-SUM(מודל_עסקה!$B$60:$B$63))-(מודל_עסקה!$B$54+מודל_עסקה!$B$17*$A10) | D10: =(מודל_עסקה!$B$59*(1+D$4))*(1-SUM(מודל_עסקה!$B$60:$B$63))-(מודל_עסקה!$B$54+מודל_עסקה!$B$17*$A10) | E10: =(מודל_עסקה!$B$59*(1+E$4))*(1-SUM(מודל_עסקה!$B$60:$B$63))-(מודל_עסקה!$B$54+מודל_עסקה!$B$17*$A10) | F10: =(מודל_עסקה!$B$59*(1+F$4))*(1-SUM(מודל_עסקה!$B$60:$B$63))-(מודל_עסקה!$B$54+מודל_עסקה!$B$17*$A10)
A13: בסיס להשוואה: רווח גולמי במודל | B13: =מודל_עסקה!B69
A15: רגישות לדריפט שוק (על אותה החזקה)
A16: שוק ($/sqft שנתי) | B16: שינוי ב-ARV | C16: רווח מתוקן
A17: קנזס סיטי +8.0% | B17: =מודל_עסקה!$B$8*0.08*מודל_עסקה!$B$30/12 | C17: =מודל_עסקה!$B$69+B17*(1-SUM(מודל_עסקה!$B$60:$B$63))-(מודל_עסקה!$B$59-מודל_עסקה!$B$8)*(1-SUM(מודל_עסקה!$B$60:$B$63))
A18: סנט לואיס +11.1% | B18: =מודל_עסקה!$B$8*0.111*מודל_עסקה!$B$30/12 | C18: =מודל_עסקה!$B$69+B18*(1-SUM(מודל_עסקה!$B$60:$B$63))-(מודל_עסקה!$B$59-מודל_עסקה!$B$8)*(1-SUM(מודל_עסקה!$B$60:$B$63))
A19: אינדיאנפוליס +0.4% | B19: =מודל_עסקה!$B$8*0.004*מודל_עסקה!$B$30/12 | C19: =מודל_עסקה!$B$69+B19*(1-SUM(מודל_עסקה!$B$60:$B$63))-(מודל_עסקה!$B$59-מודל_עסקה!$B$8)*(1-SUM(מודל_עסקה!$B$60:$B$63))
A20: קליבלנד +1.0% | B20: =מודל_עסקה!$B$8*0.01*מודל_עסקה!$B$30/12 | C20: =מודל_עסקה!$B$69+B20*(1-SUM(מודל_עסקה!$B$60:$B$63))-(מודל_עסקה!$B$59-מודל_עסקה!$B$8)*(1-SUM(מודל_עסקה!$B$60:$B$63))
A21: קולומבוס OH −0.5% | B21: =מודל_עסקה!$B$8*-0.005*מודל_עסקה!$B$30/12 | C21: =מודל_עסקה!$B$69+B21*(1-SUM(מודל_עסקה!$B$60:$B$63))-(מודל_עסקה!$B$59-מודל_עסקה!$B$8)*(1-SUM(מודל_עסקה!$B$60:$B$63))
A22: ממפיס −8.6% | B22: =מודל_עסקה!$B$8*-0.086*מודל_עסקה!$B$30/12 | C22: =מודל_עסקה!$B$69+B22*(1-SUM(מודל_עסקה!$B$60:$B$63))-(מודל_עסקה!$B$59-מודל_עסקה!$B$8)*(1-SUM(מודל_עסקה!$B$60:$B$63))

Sheet זיפים_אינדי
A1: זיפים באינדיאנפוליס — Redfin, יולי 2026
A2: ממוין: BUY BOX ← WATCH ← AVOID. המדד הקובע לפליפר הוא שינוי $/sqft, לא מדיאן המחיר.
A4: ZIP | B4: שכונה / טאונשיפ | C4: סיווג | D4: מדיאן מכירה | E4: שינוי שנתי | F4: $/sqft | G4: שינוי $/sqft | H4: DOM | I4: מכירה/מחירון | J4: % מעל מחירון | K4: Compete | L4: עסקאות/חודש | M4: שנת בנייה | N4: RRP עופרת?
A5: 46236 | B5: Geist | C5: BUY BOX | D5: 339925 | E5: -0.02 | F5: 182 | G5: 0.152 | H5: 18 | I5: 0.994 | J5: 0.281 | K5: 81 | L5: 143 | M5: 1993 | N5: =IF(M5<1978,"כן","לא")
A6: 46217 | B6: Southport / Perry | C6: BUY BOX | D6: 260942 | E6: 0.065 | F6: 145 | G6: 0.014 | H6: 17 | I6: 0.987 | J6: 0.216 | K6: 80 | L6: 152 | M6: 1990 | N6: =IF(M6<1978,"כן","לא")
A7: 46228 | B7: Crooked Creek | C7: BUY BOX | D7: 277938 | E7: -0.013 | F7: 152 | G7: 0.192 | H7: 10 | I7: 0.993 | J7: 0.207 | K7: 81 | L7: 60 | M7: 1968 | N7: =IF(M7<1978,"כן","לא")
A8: 46224 | B8: Speedway | C8: BUY BOX | D8: 219951 | E8: -0.06 | F8: 144 | G8: 0.032 | H8: 13 | I8: 0.999 | J8: 0.297 | K8: 83 | L8: 66 | M8: 1968 | N8: =IF(M8<1978,"כן","לא")
A9: 46229 | B9: Cumberland | C9: BUY BOX | D9: 222701 | E9: -0.034 | F9: 144 | G9: 0.021 | H9: 19 | I9: 0.991 | J9: 0.298 | K9: 76 | L9: 107 | M9: 1978 | N9: =IF(M9<1978,"כן","לא")
A10: 46237 | B10: Perry SE | C10: BUY BOX | D10: 281687 | E10: 0.043 | F10: 152 | G10: -0.003 | H10: 29 | I10: 0.989 | J10: 0.165 | K10: 73 | L10: 199 | M10: 1995 | N10: =IF(M10<1978,"כן","לא")
A11: 46219 | B11: Irvington | C11: BUY BOX | D11: 204954 | E11: -0.047 | F11: 114 | G11: 0.056 | H11: 24 | I11: 0.983 | J11: 0.204 | K11: 75 | L11: 166 | M11: 1957 | N11: =IF(M11<1978,"כן","לא")
A12: 46107 | B12: Beech Grove | C12: BUY BOX | D12: 199830 | E12: -0.036 | F12: 134 | G12: 0.19 | H12: 15 | I12: 1.001 | J12: 0.232 | K12: 84 | L12: 58 | M12: 1962 | N12: =IF(M12<1978,"כן","לא")
A13: 46208 | B13: Butler-Tarkington | C13: גבולי | D13: 232948 | E13: -0.109 | F13: 118 | G13: 0.135 | H13: 33 | I13: 0.976 | J13: 0.259 | K13: 59 | L13: 119 | M13: 1939 | N13: =IF(M13<1978,"כן","לא")
A14: 46240 | B14: Nora / N Meridian | C14: BUY BOX צפון | D14: 405910 | E14: -0.014 | F14: 216 | G14: 0.024 | H14: 14 | I14: 0.987 | J14: 0.284 | K14: 76 | L14: 83 | M14: 1979 | N14: =IF(M14<1978,"כן","לא")
A15: 46250 | B15: Castleton | C15: WATCH | D15: 349922 | E15: 0.049 | F15: 173 | G15: -0.025 | H15: 17 | I15: 0.993 | J15: 0.293 | K15: 79 | L15: 67 | M15: 1983 | N15: =IF(M15<1978,"כן","לא")
A16: 46220 | B16: Broad Ripple | C16: BUY BOX צפון | D16: 364919 | E16: 0.021 | F16: 153 | G16: -0.067 | H16: 9 | I16: 0.994 | J16: 0.35 | K16: 83 | L16: 229 | M16: 1959 | N16: =IF(M16<1978,"כן","לא")
... A37: 46202 | B37: Herron-Morton | C37: AVOID | D37: 462397 | E37: 0.051 | F37: 215 | G37: -0.025 | H37: 35 | I37: 0.979 | J37: 0.12 | K37: 53 | L37: 103 | M37: 1969 | N37: =IF(M37<1978,"כן","לא")
A39: מקור: redfin.com/zipcode/NNNNN/housing-market, נשלף 5.9.2026 · שנת בנייה: ACS 2020-2024 5-Yr, טבלה B25035
A40: ⚠️ 46216: 8 עסקאות בחודש — כל המדדים רעש. 46107: נתוני יוני, לא יולי.
A41: ⚠️ תבנית AVOID = $/sqft שלילי עם שיעור מכירות מעל המחירון שדווקא עולה. זו בדיוק התבנית של Bessemer 35020.
A42: ⚠️ מכירה של $250K-$350K במריון קאונטי דורשת 1,800-2,200 sqft, לא 1,400.
A43: 🟢 6.9.2026: 46220/46205/46260/46240 נוספו כשכבה צפונית אחרי בדיקה עמוקה (docs/בדיקה_זיפים_צפוניים.md). מדד מכירות חוזרות של אותו בית +3.5%-5.3% בשנה; הסימון WATCH על $/sqft של Redfin היה תמהיל.

Sheet תיק_500K
A1: מודל תיק — $500K
A3: קלט
A4: הון זמין | B4: 500000
A5: מזומן לעסקה | B5: =מודל_עסקה!B55
A6: עסקאות במקביל — תיאורטי | B6: =ROUNDDOWN(B4/B5,0)
A7: עסקאות במקביל — בפועל | B7: =MIN(B6,2) | C7: שלב א': 2 במקביל. במזומן ההון הוא האילוץ (B6), לא הקיבולת התפעולית
A8: מחזורים בשנה | B8: =מודל_עסקה!B31
A9: עסקאות בשנה | B9: =B7*B8
A11: רווח והפסד שנתי
A12: רווח לעסקה | B12: =מודל_עסקה!B69
A13: רווח גולמי שנתי | B13: =B9*B12
A14: טיסות ולינה | B14: 15000 | C14: 5 נסיעות בשנה
A15: ישויות, הנהח"ש, ביטוח, משפטי | B15: 8000
A16: חברות CIREIA ורישוי | B16: 1500
A17: בלתי צפוי | B17: 10000
A18: סה"כ G&A | B18: =SUM(B14:B17)
A19: רווח לפני מס | B19: =B13-B18
A21: מס ותשואה
A22: שיעור מס אפקטיבי | B22: 0.37 | C22: ⚠️ dealer status — פליפ הוא מלאי ⇒ הכנסה רגילה, לא רווח הון
A23: מס | B23: =B19*B22
A24: רווח נטו אחרי מס | B24: =B19-B23
A25: הון מושקע בפועל | B25: =B7*B5
A26: הון לא מחויב | B26: =B4-B25
A27: תשואה על ההון המושקע | B27: =B19/B25
A28: תשואה על כל ה-$500K (לפני מס) | B28: =B19/B4
A29: תשואה על כל ה-$500K (אחרי מס) | B29: =B24/B4

Sheet הנחות_ומקורות
A1: הנחות, מקורות ופערים פתוחים
A3: סעיף | B3: ערך | C3: מקור / הערה
A4: ATTOM — ROI לפי מדרגת רכישה | B4: <$50K: −14% · $100-200K: ~32% | C4: ATTOM Q1 2026, פורסם 18.6.2026 — המדרגה $100-200K היא הרווחית בארה"ב
A5: ATTOM — ארצי Q1 2026 | B5: רכישה $260K / מכירה $326K · רווח $66K · ROI 25.4% · 165 יום | C5: ATTOM Q1 2026 Home Flipping Report
A6: נטו לפליפר החציוני | B6: ~5.8% | C6: ATTOM עצמה. המרווח בין החציוני לרבעון העליון הוא כל העסק
A7: תקרת מס רכוש אינדיאנה | B7: 2% — לא-מאוכלס-בעלים ב-LLC | C7: IC 6-1.1-20.6-4(1). ⚠️ קוד סיווג 510/511 בטופס 11 — מיסווג מסחרי = 3%
A8: SEA 1 — ניכוי 2% חדש | B8: שווה $0 במריון קאונטי | C8: כל מחוז מס במריון חורג מ-2%. מחוזות הדונאט (1.40-1.99%) כן נהנים
A9: מס העברה | B9: $0 מדינתי | C9: אינדיאנה. ~$240 עלות ממשלתית לסבב הלוך-חזור
A10: רישום נכסים ריקים | B10: לא קיים באינדיאנפוליס | C10: ושיפוץ עם היתר פטור מקנס הנטישה — §537-43(A)(3)(a). מסיר את הסיכון שהרג את בירמינגהם
A11: עלות שיפוץ $/sqft | B11: קל 12-20 · בינוני 25-42 · גוט 45-75 | C11: אינדיאנפוליס 2026. תוספת טרום-1970: $5-15/sqft
A12: אינפלציית שיפוץ 2026 | B12: MEP, לא עץ | C12: צו 232 (6.4.2026): מכס 50%. נחושת +36%, אלומיניום +45%. עץ −0.18%
A13: היתרים | B13: מבני $390 · מטבח/אמבט ~$712 | C13: בדיקה ראשונה 15-20 ימי עסקים — כחודש זמן מת אם לא מגישים לפני הסגירה
A14: עלויות יציאה | B14: 8.3%-8.5% מה-ARV | C14: מול רווח גולמי של ~16%. חצי מהרווח
... A21: Center Township | B21: 5.7 חודשי היצע · 41 DOM · 93.1% מהמחירון המקורי | C21: המסדרון המרכזי איטי משמעותית מהמטרו
A23: ⚠️ פערים פתוחים | C23: להשלים לפני ההצעה הראשונה
A24: גודל ההטבות לקונה בדולרים | B24: חציון $5,000-6,500 · 1.9% מהמחיר · p75 2.8% | C24: נמדד 6.9.2026 מ-E3_Seller_Points (9,736 מכירות 2024-26). ⚠️ שכיחות 25% בטופס מול 46% ב-Redfin — רצפה
A25: בסיס ההשתתפות לרוח/ברד | B25: לא ידוע | C25: % מהכיסוי או $ קבוע? אינדיאנה שלישית בארה"ב באירועי ברד ב-2024. 5% על $200K = $10,000
A26: הצעת קבלן אמיתית | B26: טרם נלקחה | C26: בית אחד משנות ה-50-90. כל המודל נשען על $/sqft שהוא טווח, לא הצעה
A27: מכפיל ARV 1.18 | B27: נפסל — קומפס גאוגרפיים | C27: arv.py: 10 קומפס, קונה תופס, שומה ±25%. שגיאה חציונית 12.4%, p90 42% (backtest 6.9.2026). הטווח הוא המוצר
A28: Commissioners' Certificate Sale | B28: לא אומת שקיים במריון | C28: IC 6-1.1-24-6.1, פדיון 120 יום. הערוץ היחיד שתואם למהירות פליפ. טל' 317-327-4444
A29: האם LLC לא-תושב מוציא היתרים בעצמו? | B29: סתירה בין שני מסמכי עירייה | C29: 317-327-8700, לבקש בכתב
A30: ATTOM ברמת מטרו אינדיאנפוליס | B30: לא פורסם | C30: אינדי לא מופיעה באף אחת מ-5 רשימות Q1 2026. נדרש מנוי
A31: כלל ההצעה | B31: 72% ב-BUY BOX · 69% בצפון (היה 70%) | C31: 70% מכויל לקונה ממונף; במזומן חוזרות 2 נקודות. בצפון שגיאת ARV 18.7% ⇒ 69% לאותה כרית. decisions.md 6.9.2026

Sheet מזומן_מול_מינוף
A1: מזומן מלא מול מינוף — אותה עסקה בדיוק
A2: שתי העמודות מושכות את אותם קלטים מגיליון מודל_עסקה. משנים שם — שתיהן זזות.
A4: שורה | B4: מזומן מלא | C4: ממונף 90% LTC | D4: הערה
A5: סכום ההלוואה | B5: =0 | C5: =(מודל_עסקה!$B$9*0.90+מודל_עסקה!$B$17*1.00)
A6: עלות מימון | B6: =0 | C6: =((מודל_עסקה!$B$9*0.90+מודל_עסקה!$B$17*1.00)*0.02+(מודל_עסקה!$B$9*0.90+מודל_עסקה!$B$17*1.00)*0.095*מודל_עסקה!$B$30/12) | D6: נקודות 2% + ריבית 9.5% לתקופה
A7: סה"כ בסיס | B7: =(מודל_עסקה!$B$9+מודל_עסקה!$B$24+מודל_עסקה!$B$17+מודל_עסקה!$B$41) | C7: =((מודל_עסקה!$B$9+מודל_עסקה!$B$24+מודל_עסקה!$B$17+מודל_עסקה!$B$41)+((מודל_עסקה!$B$9*0.90+מודל_עסקה!$B$17*1.00)*0.02+(מודל_עסקה!$B$9*0.90+מודל_עסקה!$B$17*1.00)*0.095*מודל_עסקה!$B$30/12))
A8: מזומן שהושקע | B8: =(מודל_עסקה!$B$9+מודל_עסקה!$B$24+מודל_עסקה!$B$17+מודל_עסקה!$B$41) | C8: =((מודל_עסקה!$B$9+מודל_עסקה!$B$24+מודל_עסקה!$B$17+מודל_עסקה!$B$41)+((מודל_עסקה!$B$9*0.90+מודל_עסקה!$B$17*1.00)*0.02+(מודל_עסקה!$B$9*0.90+מודל_עסקה!$B$17*1.00)*0.095*מודל_עסקה!$B$30/12))-(מודל_עסקה!$B$9*0.90+מודל_עסקה!$B$17*1.00) | D8: זה מה שיוצא מהכיס
A9: תמורה נטו ממכירה | B9: =מודל_עסקה!$B$66 | C9: =מודל_עסקה!$B$66 | D9: זהה — המינוף לא נוגע ליציאה
A10: רווח גולמי | B10: =מודל_עסקה!$B$66-(מודל_עסקה!$B$9+מודל_עסקה!$B$24+מודל_עסקה!$B$17+מודל_עסקה!$B$41) | C10: =מודל_עסקה!$B$66-((מודל_עסקה!$B$9+מודל_עסקה!$B$24+מודל_עסקה!$B$17+מודל_עסקה!$B$41)+((מודל_עסקה!$B$9*0.90+מודל_עסקה!$B$17*1.00)*0.02+(מודל_עסקה!$B$9*0.90+מודל_עסקה!$B$17*1.00)*0.095*מודל_עסקה!$B$30/12)) | D10: המינוף מוריד רווח בדולרים
A11: תשואה על העלות | B11: =(מודל_עסקה!$B$66-(מודל_עסקה!$B$9+מודל_עסקה!$B$24+מודל_עסקה!$B$17+מודל_עסקה!$B$41))/(מודל_עסקה!$B$9+מודל_עסקה!$B$24+מודל_עסקה!$B$17+מודל_עסקה!$B$41) | C11: =(מודל_עסקה!$B$66-((מודל_עסקה!$B$9+מודל_עסקה!$B$24+מודל_עסקה!$B$17+מודל_עסקה!$B$41)+((מודל_עסקה!$B$9*0.90+מודל_עסקה!$B$17*1.00)*0.02+(מודל_עסקה!$B$9*0.90+מודל_עסקה!$B$17*1.00)*0.095*מודל_עסקה!$B$30/12)))/((מודל_עסקה!$B$9+מודל_עסקה!$B$24+מודל_עסקה!$B$17+מודל_עסקה!$B$41)+((מודל_עסקה!$B$9*0.90+מודל_עסקה!$B$17*1.00)*0.02+(מודל_עסקה!$B$9*0.90+מודל_עסקה!$B$17*1.00)*0.095*מודל_עסקה!$B$30/12))
A12: תשואה על המזומן (CoC) | B12: =(מודל_עסקה!$B$66-(מודל_עסקה!$B$9+מודל_עסקה!$B$24+מודל_עסקה!$B$17+מודל_עסקה!$B$41))/(מודל_עסקה!$B$9+מודל_עסקה!$B$24+מודל_עסקה!$B$17+מודל_עסקה!$B$41) | C12: =(מודל_עסקה!$B$66-((מודל_עסקה!$B$9+מודל_עסקה!$B$24+מודל_עסקה!$B$17+מודל_עסקה!$B$41)+((מודל_עסקה!$B$9*0.90+מודל_עסקה!$B$17*1.00)*0.02+(מודל_עסקה!$B$9*0.90+מודל_עסקה!$B$17*1.00)*0.095*מודל_עסקה!$B$30/12)))/(((מודל_עסקה!$B$9+מודל_עסקה!$B$24+מודל_עסקה!$B$17+מודל_עסקה!$B$41)+((מודל_עסקה!$B$9*0.90+מודל_עסקה!$B$17*1.00)*0.02+(מודל_עסקה!$B$9*0.90+מודל_עסקה!$B$17*1.00)*0.095*מודל_עסקה!$B$30/12))-(מודל_עסקה!$B$9*0.90+מודל_עסקה!$B$17*1.00)) | D12: ומעלה תשואה על ההון
A13: תשואה שנתית על המזומן | B13: =B12*מודל_עסקה!$B$31 | C13: =C12*מודל_עסקה!$B$31
A14: עסקאות במקביל על $500K | B14: =ROUNDDOWN(500000/(מודל_עסקה!$B$9+מודל_עסקה!$B$24+מודל_עסקה!$B$17+מודל_עסקה!$B$41),0) | C14: =ROUNDDOWN(500000/(((מודל_עסקה!$B$9+מודל_עסקה!$B$24+מודל_עסקה!$B$17+מודל_עסקה!$B$41)+((מודל_עסקה!$B$9*0.90+מודל_עסקה!$B$17*1.00)*0.02+(מודל_עסקה!$B$9*0.90+מודל_עסקה!$B$17*1.00)*0.095*מודל_עסקה!$B$30/12))-(מודל_עסקה!$B$9*0.90+מודל_עסקה!$B$17*1.00)),0) | D14: וזה כל ההבדל
A15: רווח שנתי — 2 במקביל | B15: =2*מודל_עסקה!$B$31*(מודל_עסקה!$B$66-(מודל_עסקה!$B$9+מודל_עסקה!$B$24+מודל_עסקה!$B$17+מודל_עסקה!$B$41)) | C15: =2*מודל_עסקה!$B$31*(מודל_עסקה!$B$66-((מודל_עסקה!$B$9+מודל_עסקה!$B$24+מודל_עסקה!$B$17+מודל_עסקה!$B$41)+((מודל_עסקה!$B$9*0.90+מודל_עסקה!$B$17*1.00)*0.02+(מודל_עסקה!$B$9*0.90+מודל_עסקה!$B$17*1.00)*0.095*מודל_עסקה!$B$30/12))) | D15: ההתחלה השמרנית
A16: רווח שנתי — במלוא הקיבולת | B16: =B14*מודל_עסקה!$B$31*(מודל_עסקה!$B$66-(מודל_עסקה!$B$9+מודל_עסקה!$B$24+מודל_עסקה!$B$17+מודל_עסקה!$B$41)) | C16: =C14*מודל_עסקה!$B$31*(מודל_עסקה!$B$66-((מודל_עסקה!$B$9+מודל_עסקה!$B$24+מודל_עסקה!$B$17+מודל_עסקה!$B$41)+((מודל_עסקה!$B$9*0.90+מודל_עסקה!$B$17*1.00)*0.02+(מודל_עסקה!$B$9*0.90+מודל_עסקה!$B$17*1.00)*0.095*מודל_עסקה!$B$30/12))) | D16: תיאורטי — הקיבולת התפעולית תחסום
A18: מה המינוף באמת עושה
A19: • המינוף מקטין את הרווח בדולרים (נקודות + ריבית) ומגדיל את התשואה על ההון. זה טרייד-אוף, לא שדרוג.
A20: • 90% LTC + 100% מימון שיפוץ = ~15% מזומן בעסקה. חריגת שיפוץ של 20% מוחקת חלק גדול מההון העצמי בעסקה.
A21: • במזומן מלא: חריגה של 20% פוגעת ברווח, לא בהישרדות. אין קריאה לכסף, אין שעון ריבית, אין דד-ליין למלווה.
A22: • הריבית רצה גם כשהבית יושב. ב-DOM של 51 יום ברמת המטרו, כל חודש עיכוב = ~1% מסכום ההלוואה.
A23: • מזומן גם מנצח בהצעות: אין תנאי מימון, אין שמאות של מלווה, סגירה ב-10-14 יום.
